Workbook

Sheet Hasenauer
A1: DBH | B1: Boomsoort | C1: Kroondiameter | D1: Bron
A2: 5 | B2: Fijnspar | C2: =EXP(VLOOKUP(B2,'Hasenauer-Variabelen'!$A$1:$D$12,3,FALSE)+VLOOKUP(B2,'Hasenauer-Variabelen'!$A$1:D11,4,FALSE)*LN(A2)) -> 2.0409981 | D2: Hasenauer (1997)
A3: 10 | B3: Fijnspar | C3: =EXP(VLOOKUP(B3,'Hasenauer-Variabelen'!$A$1:$D$12,3,FALSE)+VLOOKUP(B3,'Hasenauer-Variabelen'!$A$1:D12,4,FALSE)*LN(A3)) -> 3.1895985 | D3: Hasenauer (1997)
A4: 15 | B4: Fijnspar | C4: =EXP(VLOOKUP(B4,'Hasenauer-Variabelen'!$A$1:$D$12,3,FALSE)+VLOOKUP(B4,'Hasenauer-Variabelen'!$A$1:D13,4,FALSE)*LN(A4)) -> 4.141488 | D4: Hasenauer (1997)
A5: 20 | B5: Fijnspar | C5: =EXP(VLOOKUP(B5,'Hasenauer-Variabelen'!$A$1:$D$12,3,FALSE)+VLOOKUP(B5,'Hasenauer-Variabelen'!$A$1:D14,4,FALSE)*LN(A5)) -> 4.98459 | D5: Hasenauer (1997)
A6: 25 | B6: Fijnspar | C6: =EXP(VLOOKUP(B6,'Hasenauer-Variabelen'!$A$1:$D$12,3,FALSE)+VLOOKUP(B6,'Hasenauer-Variabelen'!$A$1:D15,4,FALSE)*LN(A6)) -> 5.7550511 | D6: Hasenauer (1997)
A7: 30 | B7: Fijnspar | C7: =EXP(VLOOKUP(B7,'Hasenauer-Variabelen'!$A$1:$D$12,3,FALSE)+VLOOKUP(B7,'Hasenauer-Variabelen'!$A$1:D16,4,FALSE)*LN(A7)) -> 6.4721686 | D7: Hasenauer (1997)
A8: 35 | B8: Fijnspar | C8: =EXP(VLOOKUP(B8,'Hasenauer-Variabelen'!$A$1:$D$12,3,FALSE)+VLOOKUP(B8,'Hasenauer-Variabelen'!$A$1:D17,4,FALSE)*LN(A8)) -> 7.1477648 | D8: Hasenauer (1997)
A9: 40 | B9: Fijnspar | C9: =EXP(VLOOKUP(B9,'Hasenauer-Variabelen'!$A$1:$D$12,3,FALSE)+VLOOKUP(B9,'Hasenauer-Variabelen'!$A$1:D18,4,FALSE)*LN(A9)) -> 7.7897382 | D9: Hasenauer (1997)
A10: 45 | B10: Fijnspar | C10: =EXP(VLOOKUP(B10,'Hasenauer-Variabelen'!$A$1:$D$12,3,FALSE)+VLOOKUP(B10,'Hasenauer-Variabelen'!$A$1:D19,4,FALSE)*LN(A10)) -> 8.4036935 | D10: Hasenauer (1997)
A11: 50 | B11: Fijnspar | C11: =EXP(VLOOKUP(B11,'Hasenauer-Variabelen'!$A$1:$D$12,3,FALSE)+VLOOKUP(B11,'Hasenauer-Variabelen'!$A$1:D20,4,FALSE)*LN(A11)) -> 8.9937871 | D11: Hasenauer (1997)
A12: 55 | B12: Fijnspar | C12: =EXP(VLOOKUP(B12,'Hasenauer-Variabelen'!$A$1:$D$12,3,FALSE)+VLOOKUP(B12,'Hasenauer-Variabelen'!$A$1:D21,4,FALSE)*LN(A12)) -> 9.5632087 | D12: Hasenauer (1997)
A13: 60 | B13: Fijnspar | C13: =EXP(VLOOKUP(B13,'Hasenauer-Variabelen'!$A$1:$D$12,3,FALSE)+VLOOKUP(B13,'Hasenauer-Variabelen'!$A$1:D22,4,FALSE)*LN(A13)) -> 10.114473 | D13: Hasenauer (1997)
... A21: 100 | B21: Fijnspar | C21: =EXP(VLOOKUP(B21,'Hasenauer-Variabelen'!$A$1:$D$12,3,FALSE)+VLOOKUP(B21,'Hasenauer-Variabelen'!$A$1:D30,4,FALSE)*LN(A21)) -> 14.055167 | D21: Hasenauer (1997)
A22: 5 | B22: Zilverden | C22: =EXP(VLOOKUP(B22,'Hasenauer-Variabelen'!$A$1:$D$12,3,FALSE)+VLOOKUP(B22,'Hasenauer-Variabelen'!$A$1:D35,4,FALSE)*LN(A22)) -> 2.6061593 | D22: Hasenauer (1997)
A23: 10 | B23: Zilverden | C23: =EXP(VLOOKUP(B23,'Hasenauer-Variabelen'!$A$1:$D$12,3,FALSE)+VLOOKUP(B23,'Hasenauer-Variabelen'!$A$1:D36,4,FALSE)*LN(A23)) -> 3.7840345 | D23: Hasenauer (1997)
A24: 15 | B24: Zilverden | C24: =EXP(VLOOKUP(B24,'Hasenauer-Variabelen'!$A$1:$D$12,3,FALSE)+VLOOKUP(B24,'Hasenauer-Variabelen'!$A$1:D37,4,FALSE)*LN(A24)) -> 4.7064364 | D24: Hasenauer (1997)
A25: 20 | B25: Zilverden | C25: =EXP(VLOOKUP(B25,'Hasenauer-Variabelen'!$A$1:$D$12,3,FALSE)+VLOOKUP(B25,'Hasenauer-Variabelen'!$A$1:D38,4,FALSE)*LN(A25)) -> 5.4942603 | D25: Hasenauer (1997)
A26: 25 | B26: Zilverden | C26: =EXP(VLOOKUP(B26,'Hasenauer-Variabelen'!$A$1:$D$12,3,FALSE)+VLOOKUP(B26,'Hasenauer-Variabelen'!$A$1:D39,4,FALSE)*LN(A26)) -> 6.1950785 | D26: Hasenauer (1997)
A27: 30 | B27: Zilverden | C27: =EXP(VLOOKUP(B27,'Hasenauer-Variabelen'!$A$1:$D$12,3,FALSE)+VLOOKUP(B27,'Hasenauer-Variabelen'!$A$1:D40,4,FALSE)*LN(A27)) -> 6.8335492 | D27: Hasenauer (1997)
A28: 35 | B28: Zilverden | C28: =EXP(VLOOKUP(B28,'Hasenauer-Variabelen'!$A$1:$D$12,3,FALSE)+VLOOKUP(B28,'Hasenauer-Variabelen'!$A$1:D41,4,FALSE)*LN(A28)) -> 7.42444 | D28: Hasenauer (1997)
A29: 40 | B29: Zilverden | C29: =EXP(VLOOKUP(B29,'Hasenauer-Variabelen'!$A$1:$D$12,3,FALSE)+VLOOKUP(B29,'Hasenauer-Variabelen'!$A$1:D42,4,FALSE)*LN(A29)) -> 7.9774367 | D29: Hasenauer (1997)
A30: 45 | B30: Zilverden | C30: =EXP(VLOOKUP(B30,'Hasenauer-Variabelen'!$A$1:$D$12,3,FALSE)+VLOOKUP(B30,'Hasenauer-Variabelen'!$A$1:D43,4,FALSE)*LN(A30)) -> 8.4993052 | D30: Hasenauer (1997)
A31: 50 | B31: Zilverden | C31: =EXP(VLOOKUP(B31,'Hasenauer-Variabelen'!$A$1:$D$12,3,FALSE)+VLOOKUP(B31,'Hasenauer-Variabelen'!$A$1:D44,4,FALSE)*LN(A31)) -> 8.9949956 | D31: Hasenauer (1997)
A32: 55 | B32: Zilverden | C32: =EXP(VLOOKUP(B32,'Hasenauer-Variabelen'!$A$1:$D$12,3,FALSE)+VLOOKUP(B32,'Hasenauer-Variabelen'!$A$1:D45,4,FALSE)*LN(A32)) -> 9.468261 | D32: Hasenauer (1997)
A33: 60 | B33: Zilverden | C33: =EXP(VLOOKUP(B33,'Hasenauer-Variabelen'!$A$1:$D$12,3,FALSE)+VLOOKUP(B33,'Hasenauer-Variabelen'!$A$1:D46,4,FALSE)*LN(A33)) -> 9.9220284 | D33: Hasenauer (1997)
... A201: 100 | B201: Linde | C201: =EXP(VLOOKUP(B201,'Hasenauer-Variabelen'!$A$1:$D$12,3,FALSE)+VLOOKUP(B201,'Hasenauer-Variabelen'!$A$1:D214,4,FALSE)*LN(A201)) -> 16.234343 | D201: Hasenauer (1997)

Sheet Hasenauer-Variabelen
A1: Soort | C1: A | D1: B
A2: Fijnspar | B2: Picea | C2: -0.3232 | D2: 0.6441
A3: Zilverden | B3: Abies | C3: 0.092 | D3: 0.538
A4: Lariks | B4: Larix | C4: -0.3396 | D4: 0.6823
A5: Grove den | B5: Pinus | C5: -0.1797 | D5: 0.6267
A6: Zwarte den | B6: Pinus nigra | C6: -0.157 | D6: 0.631
A7: Parasolden | B7: Pinus pinea | C7: -1.3154 | D7: 0.8288
A8: Beuk | B8: Fagus | C8: 0.2662 | D8: 0.6072
A9: Eik | B9: Quercus | C9: -0.3973 | D9: 0.7328
A10: Esdoorn | B10: Acer | C10: 0.418 | D10: 0.5285
A11: Es | B11: Fraxinus | C11: 0.1366 | D11: 0.6183
A12: Linde | B12: Tillia | C12: 0.1783 | D12: 0.5665

Sheet Hein
C3: =EXP(-1.119+1.918*LN(30)) -> 222.40423
C4: Opstand | D4: Opstand | E4: Boom | F4: Boom
A5: DBH | B5: Leeftijd | C5: Es | D5: Esdoorn | E5: Es | F5: Esdoorn
A6: 5 | B6: 5 | C6: =0.203*A6+0.698*-0.022*B6 -> 0.93822 | D6: =0.183*A6+0.785*-0.016*B6 -> 0.8522 | E6: =EXP(-1.119+0.918*LN(A6)) -> 1.4311295 | F6: =EXP(-0.844+0.826*LN(A6)) -> 1.6248178 | G6: =E6-C6 -> 0.49290952 | H6: =F6-D6 -> 0.77261785
A7: 10 | B7: 10 | C7: =0.203*A7+0.698*-0.022*B7 -> 1.87644 | D7: =0.183*A7+0.785*-0.016*B7 -> 1.7044 | E7: =EXP(-1.119+0.918*LN(A7)) -> 2.7041108 | F7: =EXP(-0.844+0.826*LN(A7)) -> 2.8804176 | G7: =E7-C7 -> 0.82767075 | H7: =F7-D7 -> 1.1760176
A8: 15 | B8: 15 | C8: =0.203*A8+0.698*-0.022*B8 -> 2.81466 | D8: =0.183*A8+0.785*-0.016*B8 -> 2.5566 | E8: =EXP(-1.119+0.918*LN(A8)) -> 3.9235234 | F8: =EXP(-0.844+0.826*LN(A8)) -> 4.0263065 | G8: =E8-C8 -> 1.1088634 | H8: =F8-D8 -> 1.4697065
A9: 20 | B9: 20 | C9: =0.203*A9+0.698*-0.022*B9 -> 3.75288 | D9: =0.183*A9+0.785*-0.016*B9 -> 3.4088 | E9: =EXP(-1.119+0.918*LN(A9)) -> 5.1094013 | F9: =EXP(-0.844+0.826*LN(A9)) -> 5.1062989 | G9: =E9-C9 -> 1.3565213 | H9: =F9-D9 -> 1.6974989
A10: 25 | B10: 25 | C10: =0.203*A10+0.698*-0.022*B10 -> 4.6911 | D10: =0.183*A10+0.785*-0.016*B10 -> 4.261 | E10: =EXP(-1.119+0.918*LN(A10)) -> 6.2709509 | F10: =EXP(-0.844+0.826*LN(A10)) -> 6.1397955 | G10: =E10-C10 -> 1.5798509 | H10: =F10-D10 -> 1.8787955
A11: 30 | B11: 30 | C11: =0.203*A11+0.698*-0.022*B11 -> 5.62932 | D11: =0.183*A11+0.785*-0.016*B11 -> 5.1132 | E11: =EXP(-1.119+0.918*LN(A11)) -> 7.4134743 | F11: =EXP(-0.844+0.826*LN(A11)) -> 7.1376889 | G11: =E11-C11 -> 1.7841543 | H11: =F11-D11 -> 2.0244889
A12: 35 | B12: 35 | C12: =0.203*A12+0.698*-0.022*B12 -> 6.56754 | D12: =0.183*A12+0.785*-0.016*B12 -> 5.9654 | E12: =EXP(-1.119+0.918*LN(A12)) -> 8.5404143 | F12: =EXP(-0.844+0.826*LN(A12)) -> 8.1069158 | G12: =E12-C12 -> 1.9728743 | H12: =F12-D12 -> 2.1415158
A13: 40 | B13: 40 | C13: =0.203*A13+0.698*-0.022*B13 -> 7.50576 | D13: =0.183*A13+0.785*-0.016*B13 -> 6.8176 | E13: =EXP(-1.119+0.918*LN(A13)) -> 9.6541834 | F13: =EXP(-0.844+0.826*LN(A13)) -> 9.0522598 | G13: =E13-C13 -> 2.1484234 | H13: =F13-D13 -> 2.2346598
A14: 45 | B14: 45 | C14: =0.203*A14+0.698*-0.022*B14 -> 8.44398 | D14: =0.183*A14+0.785*-0.016*B14 -> 7.6698 | E14: =EXP(-1.119+0.918*LN(A14)) -> 10.756564 | F14: =EXP(-0.844+0.826*LN(A14)) -> 9.9772073 | G14: =E14-C14 -> 2.3125839 | H14: =F14-D14 -> 2.3074073
A15: 50 | B15: 50 | C15: =0.203*A15+0.698*-0.022*B15 -> 9.3822 | D15: =0.183*A15+0.785*-0.016*B15 -> 8.522 | E15: =EXP(-1.119+0.918*LN(A15)) -> 11.848925 | F15: =EXP(-0.844+0.826*LN(A15)) -> 10.884405 | G15: =E15-C15 -> 2.4667247 | H15: =F15-D15 -> 2.3624047
A16: 55 | B16: 55 | C16: =0.203*A16+0.698*-0.022*B16 -> 10.32042 | D16: =0.183*A16+0.785*-0.016*B16 -> 9.3742 | E16: =EXP(-1.119+0.918*LN(A16)) -> 12.932349 | F16: =EXP(-0.844+0.826*LN(A16)) -> 11.775925 | G16: =E16-C16 -> 2.6119292 | H16: =F16-D16 -> 2.4017252
A17: 60 | B17: 60 | C17: =0.203*A17+0.698*-0.022*B17 -> 11.25864 | D17: =0.183*A17+0.785*-0.016*B17 -> 10.2264 | E17: =EXP(-1.119+0.918*LN(A17)) -> 14.007716 | F17: =EXP(-0.844+0.826*LN(A17)) -> 12.653434 | G17: =E17-C17 -> 2.7490758 | H17: =F17-D17 -> 2.4270336
A18: 65 | B18: 65 | C18: =0.203*A18+0.698*-0.022*B18 -> 12.19686 | D18: =0.183*A18+0.785*-0.016*B18 -> 11.0786 | E18: =EXP(-1.119+0.918*LN(A18)) -> 15.07575 | F18: =EXP(-0.844+0.826*LN(A18)) -> 13.518294 | G18: =E18-C18 -> 2.8788903 | H18: =F18-D18 -> 2.4396941
A19: 70 | B19: 70 | C19: =0.203*A19+0.698*-0.022*B19 -> 13.13508 | D19: =0.183*A19+0.785*-0.016*B19 -> 11.9308 | E19: =EXP(-1.119+0.918*LN(A19)) -> 16.137062 | F19: =EXP(-0.844+0.826*LN(A19)) -> 14.371644 | G19: =E19-C19 -> 3.0019823 | H19: =F19-D19 -> 2.4408436 | I19: =C19-D19 -> 1.20428
A20: 75 | B20: 75 | C20: =0.203*A20+0.698*-0.022*B20 -> 14.0733 | D20: =0.183*A20+0.785*-0.016*B20 -> 12.783 | E20: =EXP(-1.119+0.918*LN(A20)) -> 17.192171 | F20: =EXP(-0.844+0.826*LN(A20)) -> 15.214443 | G20: =E20-C20 -> 3.1188707 | H20: =F20-D20 -> 2.4314431
A21: 80 | B21: 80 | C21: =0.203*A21+0.698*-0.022*B21 -> 15.01152 | D21: =0.183*A21+0.785*-0.016*B21 -> 13.6352 | E21: =EXP(-1.119+0.918*LN(A21)) -> 18.241522 | F21: =EXP(-0.844+0.826*LN(A21)) -> 16.047515 | G21: =E21-C21 -> 3.2300025 | H21: =F21-D21 -> 2.4123149
A22: 85 | B22: 85 | C22: =0.203*A22+0.698*-0.022*B22 -> 15.94974 | D22: =0.183*A22+0.785*-0.016*B22 -> 14.4874 | E22: =EXP(-1.119+0.918*LN(A22)) -> 19.285506 | F22: =EXP(-0.844+0.826*LN(A22)) -> 16.87157 | G22: =E22-C22 -> 3.3357665 | H22: =F22-D22 -> 2.3841697
A23: 90 | B23: 90 | C23: =0.203*A23+0.698*-0.022*B23 -> 16.88796 | E23: =EXP(-1.119+0.918*LN(A23)) -> 20.324464 | F23: =EXP(-0.844+0.826*LN(A23)) -> 17.687228 | G23: =E23-C23 -> 3.4365039 | H23: =F23-D23 -> 17.687228
A24: 95 | B24: 95 | C24: =0.203*A24+0.698*-0.022*B24 -> 17.82618 | E24: =EXP(-1.119+0.918*LN(A24)) -> 21.358696 | F24: =EXP(-0.844+0.826*LN(A24)) -> 18.495035 | G24: =E24-C24 -> 3.5325165 | H24: =F24-D24 -> 18.495035
A25: 100 | B25: 100 | E25: =EXP(-1.119+0.918*LN(A25)) -> 22.388473 | F25: =EXP(-0.844+0.826*LN(A25)) -> 19.295474 | G25: =E25-C25 -> 22.388473 | H25: =F25-D25 -> 19.295474

Sheet Hein_onder_elkaar
A1: DBH | B1: Leeftijd | C1: Boomsoort | D1: Kroon
A2: 5 | B2: 5 | C2: Es (opstand) | D2: =0.203*A2+0.698*-0.022*B2 -> 0.93822
A3: 10 | B3: 10 | C3: Es (opstand) | D3: =0.203*A3+0.698*-0.022*B3 -> 1.87644
A4: 15 | B4: 15 | C4: Es (opstand) | D4: =0.203*A4+0.698*-0.022*B4 -> 2.81466
A5: 20 | B5: 20 | C5: Es (opstand) | D5: =0.203*A5+0.698*-0.022*B5 -> 3.75288
A6: 25 | B6: 25 | C6: Es (opstand) | D6: =0.203*A6+0.698*-0.022*B6 -> 4.6911
A7: 30 | B7: 30 | C7: Es (opstand) | D7: =0.203*A7+0.698*-0.022*B7 -> 5.62932
A8: 35 | B8: 35 | C8: Es (opstand) | D8: =0.203*A8+0.698*-0.022*B8 -> 6.56754
A9: 40 | B9: 40 | C9: Es (opstand) | D9: =0.203*A9+0.698*-0.022*B9 -> 7.50576
A10: 45 | B10: 45 | C10: Es (opstand) | D10: =0.203*A10+0.698*-0.022*B10 -> 8.44398
A11: 50 | B11: 50 | C11: Es (opstand) | D11: =0.203*A11+0.698*-0.022*B11 -> 9.3822
A12: 55 | B12: 55 | C12: Es (opstand) | D12: =0.203*A12+0.698*-0.022*B12 -> 10.32042
A13: 60 | B13: 60 | C13: Es (opstand) | D13: =0.203*A13+0.698*-0.022*B13 -> 11.25864
... A20: 95 | B20: 95 | C20: Es (opstand) | D20: =0.203*A20+0.698*-0.022*B20 -> 17.82618
A21: 100 | B21: 100 | C21: Es (opstand)
A22: 5 | B22: 5 | C22: Esdoorn (opstand) | D22: =0.183*A22+0.785*-0.016*B22 -> 0.8522
A23: 10 | B23: 10 | C23: Esdoorn (opstand) | D23: =0.183*A23+0.785*-0.016*B23 -> 1.7044
A24: 15 | B24: 15 | C24: Esdoorn (opstand) | D24: =0.183*A24+0.785*-0.016*B24 -> 2.5566
A25: 20 | B25: 20 | C25: Esdoorn (opstand) | D25: =0.183*A25+0.785*-0.016*B25 -> 3.4088
A26: 25 | B26: 25 | C26: Esdoorn (opstand) | D26: =0.183*A26+0.785*-0.016*B26 -> 4.261
A27: 30 | B27: 30 | C27: Esdoorn (opstand) | D27: =0.183*A27+0.785*-0.016*B27 -> 5.1132
A28: 35 | B28: 35 | C28: Esdoorn (opstand) | D28: =0.183*A28+0.785*-0.016*B28 -> 5.9654
A29: 40 | B29: 40 | C29: Esdoorn (opstand) | D29: =0.183*A29+0.785*-0.016*B29 -> 6.8176
A30: 45 | B30: 45 | C30: Esdoorn (opstand) | D30: =0.183*A30+0.785*-0.016*B30 -> 7.6698
A31: 50 | B31: 50 | C31: Esdoorn (opstand) | D31: =0.183*A31+0.785*-0.016*B31 -> 8.522
A32: 55 | B32: 55 | C32: Esdoorn (opstand) | D32: =0.183*A32+0.785*-0.016*B32 -> 9.3742
A33: 60 | B33: 60 | C33: Esdoorn (opstand) | D33: =0.183*A33+0.785*-0.016*B33 -> 10.2264
... A38: 85 | B38: 85 | C38: Esdoorn (opstand) | D38: =0.183*A38+0.785*-0.016*B38 -> 14.4874
A39: 90 | B39: 90 | C39: Esdoorn (opstand)
A40: 95 | B40: 95 | C40: Esdoorn (opstand)
A41: 100 | B41: 100 | C41: Esdoorn (opstand)
A42: 5 | B42: 5 | C42: Es (solitair) | D42: =EXP(-1.119+0.918*LN(A42)) -> 1.4311295
A43: 10 | B43: 10 | C43: Es (solitair) | D43: =EXP(-1.119+0.918*LN(A43)) -> 2.7041108
A44: 15 | B44: 15 | C44: Es (solitair) | D44: =EXP(-1.119+0.918*LN(A44)) -> 3.9235234
A45: 20 | B45: 20 | C45: Es (solitair) | D45: =EXP(-1.119+0.918*LN(A45)) -> 5.1094013
A46: 25 | B46: 25 | C46: Es (solitair) | D46: =EXP(-1.119+0.918*LN(A46)) -> 6.2709509
A47: 30 | B47: 30 | C47: Es (solitair) | D47: =EXP(-1.119+0.918*LN(A47)) -> 7.4134743
A48: 35 | B48: 35 | C48: Es (solitair) | D48: =EXP(-1.119+0.918*LN(A48)) -> 8.5404143
A49: 40 | B49: 40 | C49: Es (solitair) | D49: =EXP(-1.119+0.918*LN(A49)) -> 9.6541834
A50: 45 | B50: 45 | C50: Es (solitair) | D50: =EXP(-1.119+0.918*LN(A50)) -> 10.756564
...

Sheet Hemery-Variabelen
B4: intercept | C4: Helling
B5: a | C5: b
A6: Gewone esdoorn | B6: 0.69189 | C6: 18.677
A7: Berk | B7: 0.97524 | C7: 16.1512
A8: Tamme kastanje | B8: 2.79271 | C8: 10.6684
A9: Beuk | B9: 1.13312 | C9: 15.2331
A10: Es | B10: 0.7581 | C10: 20.3565
A11: Walnoot | B11: 2.75266 | C11: 18.1646
A12: Populier | B12: 0.80097 | C12: 18.9502
A13: Zoete kers | B13: 1.76 | C13: 15.4
A14: Inlandse eik | B14: 1.71733 | C14: 15.6159
A15: Lijsterbes | B15: 1.09576 | C15: 18.449
A16: Winterlinde | B16: 2.25928 | C16: 11.4408

Sheet Hemery_onder_elkaar
A1: DBH | B1: Boomsoort | C1: Kroondiameter | D1: Kd-ratio | E1: N
A2: 5 | B2: Gewone esdoorn | C2: =VLOOKUP($B2,'Hemery-Variabelen'!$A$5:$C$16,3,FALSE)*(Hemery_onder_elkaar!A2/100)+VLOOKUP($B2,'Hemery-Variabelen'!$A$5:$C$16,2,FALSE) -> 1.62574 | D2: =C2/(A2/100) -> 32.5148 | E2: =10^4/C2^2 -> 3783.5355 | F2: =10000*79%/A2*C2^2*0.785 -> 3278.1508 | G2: =A2/100*C2^2*0.785 -> 0.10373895 | H2: =7900/G2 -> 76152.69
A3: 10 | B3: Gewone esdoorn | C3: =VLOOKUP($B3,'Hemery-Variabelen'!$A$5:$C$16,3,FALSE)*(Hemery_onder_elkaar!A3/100)+VLOOKUP($B3,'Hemery-Variabelen'!$A$5:$C$16,2,FALSE) -> 2.55959 | D3: =C3/(A3/100) -> 25.5959 | E3: =10^4/C3^2 -> 1526.3678 | F3: =10000*79%/A3*C3^2*0.785 -> 4062.9133 | G3: =A3/100*C3^2*0.785 -> 0.51429283 | H3: =7900/G3 -> 15360.899
A4: 15 | B4: Gewone esdoorn | C4: =VLOOKUP($B4,'Hemery-Variabelen'!$A$5:$C$16,3,FALSE)*(Hemery_onder_elkaar!A4/100)+VLOOKUP($B4,'Hemery-Variabelen'!$A$5:$C$16,2,FALSE) -> 3.49344 | D4: =C4/(A4/100) -> 23.2896 | E4: =10^4/C4^2 -> 819.39521 | F4: =10000*79%/A4*C4^2*0.785 -> 5045.5913 | G4: =A4/100*C4^2*0.785 -> 1.4370355 | H4: =7900/G4 -> 5497.4286
A5: 20 | B5: Gewone esdoorn | C5: =VLOOKUP($B5,'Hemery-Variabelen'!$A$5:$C$16,3,FALSE)*(Hemery_onder_elkaar!A5/100)+VLOOKUP($B5,'Hemery-Variabelen'!$A$5:$C$16,2,FALSE) -> 4.42729 | D5: =C5/(A5/100) -> 22.13645 | E5: =10^4/C5^2 -> 510.18074 | F5: =10000*79%/A5*C5^2*0.785 -> 6077.7481 | G5: =A5/100*C5^2*0.785 -> 3.0773408 | H5: =7900/G5 -> 2567.1515
A6: 25 | B6: Gewone esdoorn | C6: =VLOOKUP($B6,'Hemery-Variabelen'!$A$5:$C$16,3,FALSE)*(Hemery_onder_elkaar!A6/100)+VLOOKUP($B6,'Hemery-Variabelen'!$A$5:$C$16,2,FALSE) -> 5.36114 | D6: =C6/(A6/100) -> 21.44456 | E6: =10^4/C6^2 -> 347.92505 | F6: =10000*79%/A6*C6^2*0.785 -> 7129.6964 | G6: =A6/100*C6^2*0.785 -> 5.6405826 | H6: =7900/G6 -> 1400.5645
A7: 30 | B7: Gewone esdoorn | C7: =VLOOKUP($B7,'Hemery-Variabelen'!$A$5:$C$16,3,FALSE)*(Hemery_onder_elkaar!A7/100)+VLOOKUP($B7,'Hemery-Variabelen'!$A$5:$C$16,2,FALSE) -> 6.29499 | D7: =C7/(A7/100) -> 20.9833 | E7: =10^4/C7^2 -> 252.35384 | F7: =10000*79%/A7*C7^2*0.785 -> 8191.5405 | G7: =A7/100*C7^2*0.785 -> 9.3321347 | H7: =7900/G7 -> 846.53728
A8: 35 | B8: Gewone esdoorn | C8: =VLOOKUP($B8,'Hemery-Variabelen'!$A$5:$C$16,3,FALSE)*(Hemery_onder_elkaar!A8/100)+VLOOKUP($B8,'Hemery-Variabelen'!$A$5:$C$16,2,FALSE) -> 7.22884 | D8: =C8/(A8/100) -> 20.653829 | E8: =10^4/C8^2 -> 191.36512 | F8: =10000*79%/A8*C8^2*0.785 -> 9259.0393 | G8: =A8/100*C8^2*0.785 -> 14.357371 | H8: =7900/G8 -> 550.24001
A9: 40 | B9: Gewone esdoorn | C9: =VLOOKUP($B9,'Hemery-Variabelen'!$A$5:$C$16,3,FALSE)*(Hemery_onder_elkaar!A9/100)+VLOOKUP($B9,'Hemery-Variabelen'!$A$5:$C$16,2,FALSE) -> 8.16269 | D9: =C9/(A9/100) -> 20.406725 | E9: =10^4/C9^2 -> 150.08365 | F9: =10000*79%/A9*C9^2*0.785 -> 10330.072 | G9: =A9/100*C9^2*0.785 -> 20.921666 | H9: =7900/G9 -> 377.599
A10: 45 | B10: Gewone esdoorn | C10: =VLOOKUP($B10,'Hemery-Variabelen'!$A$5:$C$16,3,FALSE)*(Hemery_onder_elkaar!A10/100)+VLOOKUP($B10,'Hemery-Variabelen'!$A$5:$C$16,2,FALSE) -> 9.09654 | D10: =C10/(A10/100) -> 20.214533 | E10: =10^4/C10^2 -> 120.85024 | F10: =10000*79%/A10*C10^2*0.785 -> 11403.462 | G10: =A10/100*C10^2*0.785 -> 29.230392 | H10: =7900/G10 -> 270.26665
A11: 50 | B11: Gewone esdoorn | C11: =VLOOKUP($B11,'Hemery-Variabelen'!$A$5:$C$16,3,FALSE)*(Hemery_onder_elkaar!A11/100)+VLOOKUP($B11,'Hemery-Variabelen'!$A$5:$C$16,2,FALSE) -> 10.03039 | D11: =C11/(A11/100) -> 20.06078 | E11: =10^4/C11^2 -> 99.394959 | F11: =10000*79%/A11*C11^2*0.785 -> 12478.5 | G11: =A11/100*C11^2*0.785 -> 39.488924 | H11: =7900/G11 -> 200.0561
A12: 55 | B12: Gewone esdoorn | C12: =VLOOKUP($B12,'Hemery-Variabelen'!$A$5:$C$16,3,FALSE)*(Hemery_onder_elkaar!A12/100)+VLOOKUP($B12,'Hemery-Variabelen'!$A$5:$C$16,2,FALSE) -> 10.96424 | D12: =C12/(A12/100) -> 19.934982 | E12: =10^4/C12^2 -> 83.1846 | F12: =10000*79%/A12*C12^2*0.785 -> 13554.738 | G12: =A12/100*C12^2*0.785 -> 51.902636 | H12: =7900/G12 -> 152.20807
A13: 60 | B13: Gewone esdoorn | C13: =VLOOKUP($B13,'Hemery-Variabelen'!$A$5:$C$16,3,FALSE)*(Hemery_onder_elkaar!A13/100)+VLOOKUP($B13,'Hemery-Variabelen'!$A$5:$C$16,2,FALSE) -> 11.89809 | D13: =C13/(A13/100) -> 19.83015 | E13: =10^4/C13^2 -> 70.639156 | F13: =10000*79%/A13*C13^2*0.785 -> 14631.875 | G13: =A13/100*C13^2*0.785 -> 66.676901 | H13: =7900/G13 -> 118.48181
... A86: 65 | B86: Walnoot | C86: =VLOOKUP($B86,'Hemery-Variabelen'!$A$5:$C$16,3,FALSE)*(Hemery_onder_elkaar!A86/100)+VLOOKUP($B86,'Hemery-Variabelen'!$A$5:$C$16,2,FALSE) -> 14.55965 | D86: =C86/(A86/100) -> 22.399462 | E86: =10^4/C86^2 -> 47.173503 | F86: =10000*79%/A86*C86^2*0.785 -> 20224.848 | G86: =A86/100*C86^2*0.785 -> 108.16453 | H86: =7900/G86 -> 73.036879
A87: 70 | B87: Walnoot | C87: =VLOOKUP($B87,'Hemery-Variabelen'!$A$5:$C$16,2,FALSE)+VLOOKUP($B87,'Hemery-Variabelen'!$A$5:$C$16,3,FALSE)*A87/100 -> 15.46788 | D87: =C87/(A87/100) -> 22.096971 | E87: =10^4/C87^2 -> 41.796355 | F87: =10000*79%/A87*C87^2*0.785 -> 21196.312 | G87: =A87/100*C87^2*0.785 -> 131.47079 | H87: =7900/G87 -> 60.089392
A88: 75 | B88: Walnoot | C88: =VLOOKUP($B88,'Hemery-Variabelen'!$A$5:$C$16,2,FALSE)+VLOOKUP($B88,'Hemery-Variabelen'!$A$5:$C$16,3,FALSE)*A88/100 -> 16.37611 | D88: =C88/(A88/100) -> 21.834813 | E88: =10^4/C88^2 -> 37.288808 | F88: =10000*79%/A88*C88^2*0.785 -> 22174.66 | G88: =A88/100*C88^2*0.785 -> 157.8892 | H88: =7900/G88 -> 50.035089
A89: 80 | B89: Walnoot | C89: =VLOOKUP($B89,'Hemery-Variabelen'!$A$5:$C$16,3,FALSE)*(Hemery_onder_elkaar!A89/100)+VLOOKUP($B89,'Hemery-Variabelen'!$A$5:$C$16,2,FALSE) -> 17.28434 | D89: =C89/(A89/100) -> 21.605425 | E89: =10^4/C89^2 -> 33.472982 | F89: =10000*79%/A89*C89^2*0.785 -> 23158.603 | G89: =A89/100*C89^2*0.785 -> 187.614 | H89: =7900/G89 -> 42.107732
A90: 10 | B90: Populier | C90: =VLOOKUP($B90,'Hemery-Variabelen'!$A$5:$C$16,3,FALSE)*(Hemery_onder_elkaar!A90/100)+VLOOKUP($B90,'Hemery-Variabelen'!$A$5:$C$16,2,FALSE) -> 2.69599 | D90: =C90/(A90/100) -> 26.9599 | E90: =10^4/C90^2 -> 1375.8258 | F90: =10000*79%/A90*C90^2*0.785 -> 4507.4747 | G90: =A90/100*C90^2*0.785 -> 0.57056642 | H90: =7900/G90 -> 13845.89
A91: 15 | B91: Populier | C91: =VLOOKUP($B91,'Hemery-Variabelen'!$A$5:$C$16,3,FALSE)*(Hemery_onder_elkaar!A91/100)+VLOOKUP($B91,'Hemery-Variabelen'!$A$5:$C$16,2,FALSE) -> 3.6435 | D91: =C91/(A91/100) -> 24.29 | E91: =10^4/C91^2 -> 753.29043 | F91: =10000*79%/A91*C91^2*0.785 -> 5488.3656 | G91: =A91/100*C91^2*0.785 -> 1.5631421 | H91: =7900/G91 -> 5053.9231
A92: 20 | B92: Populier | C92: =VLOOKUP($B92,'Hemery-Variabelen'!$A$5:$C$16,3,FALSE)*(Hemery_onder_elkaar!A92/100)+VLOOKUP($B92,'Hemery-Variabelen'!$A$5:$C$16,2,FALSE) -> 4.59101 | D92: =C92/(A92/100) -> 22.95505 | E92: =10^4/C92^2 -> 474.44243 | F92: =10000*79%/A92*C92^2*0.785 -> 6535.5664 | G92: =A92/100*C92^2*0.785 -> 3.3091475 | H92: =7900/G92 -> 2387.3218
A93: 25 | B93: Populier | C93: =VLOOKUP($B93,'Hemery-Variabelen'!$A$5:$C$16,3,FALSE)*(Hemery_onder_elkaar!A93/100)+VLOOKUP($B93,'Hemery-Variabelen'!$A$5:$C$16,2,FALSE) -> 5.53852 | D93: =C93/(A93/100) -> 22.15408 | E93: =10^4/C93^2 -> 325.9962 | F93: =10000*79%/A93*C93^2*0.785 -> 7609.2911 | G93: =A93/100*C93^2*0.785 -> 6.0200087 | H93: =7900/G93 -> 1312.2905
A94: 30 | B94: Populier | C94: =VLOOKUP($B94,'Hemery-Variabelen'!$A$5:$C$16,3,FALSE)*(Hemery_onder_elkaar!A94/100)+VLOOKUP($B94,'Hemery-Variabelen'!$A$5:$C$16,2,FALSE) -> 6.48603 | D94: =C94/(A94/100) -> 21.6201 | E94: =10^4/C94^2 -> 237.70707 | F94: =10000*79%/A94*C94^2*0.785 -> 8696.2777 | G94: =A94/100*C94^2*0.785 -> 9.9071518 | H94: =7900/G94 -> 797.40375
A95: 35 | B95: Populier | C95: =VLOOKUP($B95,'Hemery-Variabelen'!$A$5:$C$16,3,FALSE)*(Hemery_onder_elkaar!A95/100)+VLOOKUP($B95,'Hemery-Variabelen'!$A$5:$C$16,2,FALSE) -> 7.43354 | D95: =C95/(A95/100) -> 21.238686 | E95: =10^4/C95^2 -> 180.97085 | F95: =10000*79%/A95*C95^2*0.785 -> 9790.8426 | G95: =A95/100*C95^2*0.785 -> 15.182003 | H95: =7900/G95 -> 520.35295
A96: 40 | B96: Populier | C96: =VLOOKUP($B96,'Hemery-Variabelen'!$A$5:$C$16,3,FALSE)*(Hemery_onder_elkaar!A96/100)+VLOOKUP($B96,'Hemery-Variabelen'!$A$5:$C$16,2,FALSE) -> 8.38105 | D96: =C96/(A96/100) -> 20.952625 | E96: =10^4/C96^2 -> 142.36497 | F96: =10000*79%/A96*C96^2*0.785 -> 10890.144 | G96: =A96/100*C96^2*0.785 -> 22.055988 | H96: =7900/G96 -> 358.17938
A97: 45 | B97: Populier | C97: =VLOOKUP($B97,'Hemery-Variabelen'!$A$5:$C$16,3,FALSE)*(Hemery_onder_elkaar!A97/100)+VLOOKUP($B97,'Hemery-Variabelen'!$A$5:$C$16,2,FALSE) -> 9.32856 | D97: =C97/(A97/100) -> 20.730133 | E97: =10^4/C97^2 -> 114.91343 | F97: =10000*79%/A97*C97^2*0.785 -> 11992.603 | G97: =A97/100*C97^2*0.785 -> 30.740533 | H97: =7900/G97 -> 256.98969
A98: 50 | B98: Populier | C98: =VLOOKUP($B98,'Hemery-Variabelen'!$A$5:$C$16,3,FALSE)*(Hemery_onder_elkaar!A98/100)+VLOOKUP($B98,'Hemery-Variabelen'!$A$5:$C$16,2,FALSE) -> 10.27607 | D98: =C98/(A98/100) -> 20.55214 | E98: =10^4/C98^2 -> 94.699109 | F98: =10000*79%/A98*C98^2*0.785 -> 13097.272 | G98: =A98/100*C98^2*0.785 -> 41.447064 | H98: =7900/G98 -> 190.60458
A99: 55 | B99: Populier | C99: =VLOOKUP($B99,'Hemery-Variabelen'!$A$5:$C$16,3,FALSE)*(Hemery_onder_elkaar!A99/100)+VLOOKUP($B99,'Hemery-Variabelen'!$A$5:$C$16,2,FALSE) -> 11.22358 | D99: =C99/(A99/100) -> 20.406509 | E99: =10^4/C99^2 -> 79.384769 | F99: =10000*79%/A99*C99^2*0.785 -> 14203.549 | G99: =A99/100*C99^2*0.785 -> 54.387007 | H99: =7900/G99 -> 145.25528
A100: 60 | B100: Populier | C100: =VLOOKUP($B100,'Hemery-Variabelen'!$A$5:$C$16,3,FALSE)*(Hemery_onder_elkaar!A100/100)+VLOOKUP($B100,'Hemery-Variabelen'!$A$5:$C$16,2,FALSE) -> 12.17109 | D100: =C100/(A100/100) -> 20.28515 | E100: =10^4/C100^2 -> 67.505794 | F100: =10000*79%/A100*C100^2*0.785 -> 15311.031 | G100: =A100/100*C100^2*0.785 -> 69.771788 | H100: =7900/G100 -> 113.22628
... A156: 80 | B156: Winterlinde | C156: =VLOOKUP($B156,'Hemery-Variabelen'!$A$5:$C$16,3,FALSE)*(Hemery_onder_elkaar!A156/100)+VLOOKUP($B156,'Hemery-Variabelen'!$A$5:$C$16,2,FALSE) -> 11.41192 | D156: =C156/(A156/100) -> 14.2649 | E156: =10^4/C156^2 -> 76.786092 | F156: =10000*79%/A156*C156^2*0.785 -> 10095.416 | G156: =A156/100*C156^2*0.785 -> 81.785645 | H156: =7900/G156 -> 96.593969
